Workbook

Sheet tabela
A1: Jogo | B1: DS | C1: Dia local | D1: Dia Br | E1: Hora Br | F1: Fase | G1: Seleção 1 | H1: Seleção 2 | I1: considerar | J1: Jogo Web App | K1: golsSel1 | L1: golsSel2 | M1: permiteEdicaoResultado
A2: 1 | B2: =TEXT(D2,"ddd") -> Fri | C2: =IF(E2>0.5,D2,D2-1) -> 46164 | D2: 46164 | E2: 0.66666667 | F2: grupo A | G2: México | H2: África do Sul | I2: =IF(OR(LEFT(F2,5)<>"grupo",IFERROR(VLOOKUP(G2,chave!$B$2:$C$49,2,FALSE),"x")="x",IFERROR(VLOOKUP(H2,chave!$B$2:$C$49,2,FALSE),"x")="x"),1,0) -> 1 | J2: =TEXT(D2,"dd/mm")&" "&TEXT(E2,"HH:MM")&" - "&F2&" - "&G2&" x "&H2 -> 22/05 16:00 - grupo A - México x África do Sul | K2: 9 | L2: 9 | M2: 1
A3: 2 | B3: =TEXT(D3,"ddd") -> Thu | C3: =IF(E3>0.5,D3,D3-1) -> 46184 | D3: 46184 | E3: 0.95833333 | F3: grupo A | G3: Coreia do Sul | H3: Rep. Tcheca | I3: =IF(OR(LEFT(F3,5)<>"grupo",IFERROR(VLOOKUP(G3,chave!$B$2:$C$49,2,FALSE),"x")="x",IFERROR(VLOOKUP(H3,chave!$B$2:$C$49,2,FALSE),"x")="x"),1,0) -> 0 | J3: =TEXT(D3,"dd/mm")&" "&TEXT(E3,"HH:MM")&" - "&F3&" - "&G3&" x "&H3 -> 11/06 23:00 - grupo A - Coreia do Sul x Rep. Tcheca | K3: 1 | L3: 2 | M3: 1
A4: 3 | B4: =TEXT(D4,"ddd") -> Fri | C4: =IF(E4>0.5,D4,D4-1) -> 46185 | D4: 46185 | E4: 0.66666667 | F4: grupo B | G4: Canadá | H4: Bósnia e H | I4: =IF(OR(LEFT(F4,5)<>"grupo",IFERROR(VLOOKUP(G4,chave!$B$2:$C$49,2,FALSE),"x")="x",IFERROR(VLOOKUP(H4,chave!$B$2:$C$49,2,FALSE),"x")="x"),1,0) -> 1 | J4: =TEXT(D4,"dd/mm")&" "&TEXT(E4,"HH:MM")&" - "&F4&" - "&G4&" x "&H4 -> 12/06 16:00 - grupo B - Canadá x Bósnia e H | K4: 1 | L4: 2 | M4: 1
A5: 4 | B5: =TEXT(D5,"ddd") -> Fri | C5: =IF(E5>0.5,D5,D5-1) -> 46185 | D5: 46185 | E5: 0.91666667 | F5: grupo D | G5: Estados Unidos | H5: Paraguai | I5: =IF(OR(LEFT(F5,5)<>"grupo",IFERROR(VLOOKUP(G5,chave!$B$2:$C$49,2,FALSE),"x")="x",IFERROR(VLOOKUP(H5,chave!$B$2:$C$49,2,FALSE),"x")="x"),1,0) -> 1 | J5: =TEXT(D5,"dd/mm")&" "&TEXT(E5,"HH:MM")&" - "&F5&" - "&G5&" x "&H5 -> 12/06 22:00 - grupo D - Estados Unidos x Paraguai | K5: 0 | M5: 1
A6: 5 | B6: =TEXT(D6,"ddd") -> Sat | C6: =IF(E6>0.5,D6,D6-1) -> 46186 | D6: 46186 | E6: 0.66666667 | F6: grupo B | G6: Catar | H6: Suíça | I6: =IF(OR(LEFT(F6,5)<>"grupo",IFERROR(VLOOKUP(G6,chave!$B$2:$C$49,2,FALSE),"x")="x",IFERROR(VLOOKUP(H6,chave!$B$2:$C$49,2,FALSE),"x")="x"),1,0) -> 0 | J6: =TEXT(D6,"dd/mm")&" "&TEXT(E6,"HH:MM")&" - "&F6&" - "&G6&" x "&H6 -> 13/06 16:00 - grupo B - Catar x Suíça | K6: 0 | M6: 1
A7: 6 | B7: =TEXT(D7,"ddd") -> Sat | C7: =IF(E7>0.5,D7,D7-1) -> 46186 | D7: 46186 | E7: 0.79166667 | F7: grupo C | G7: Brasil | H7: Marrocos | I7: =IF(OR(LEFT(F7,5)<>"grupo",IFERROR(VLOOKUP(G7,chave!$B$2:$C$49,2,FALSE),"x")="x",IFERROR(VLOOKUP(H7,chave!$B$2:$C$49,2,FALSE),"x")="x"),1,0) -> 1 | J7: =TEXT(D7,"dd/mm")&" "&TEXT(E7,"HH:MM")&" - "&F7&" - "&G7&" x "&H7 -> 13/06 19:00 - grupo C - Brasil x Marrocos | K7: 0 | M7: 1
A8: 7 | B8: =TEXT(D8,"ddd") -> Sat | C8: =IF(E8>0.5,D8,D8-1) -> 46186 | D8: 46186 | E8: 0.91666667 | F8: grupo C | G8: Haiti | H8: Escócia | I8: =IF(OR(LEFT(F8,5)<>"grupo",IFERROR(VLOOKUP(G8,chave!$B$2:$C$49,2,FALSE),"x")="x",IFERROR(VLOOKUP(H8,chave!$B$2:$C$49,2,FALSE),"x")="x"),1,0) -> 0 | J8: =TEXT(D8,"dd/mm")&" "&TEXT(E8,"HH:MM")&" - "&F8&" - "&G8&" x "&H8 -> 13/06 22:00 - grupo C - Haiti x Escócia | K8: 0 | M8: 1
A9: 8 | B9: =TEXT(D9,"ddd") -> Sun | C9: =IF(E9>0.5,D9,D9-1) -> 46186 | D9: 46187 | E9: 0.041666667 | F9: grupo D | G9: Austrália | H9: Turquia | I9: =IF(OR(LEFT(F9,5)<>"grupo",IFERROR(VLOOKUP(G9,chave!$B$2:$C$49,2,FALSE),"x")="x",IFERROR(VLOOKUP(H9,chave!$B$2:$C$49,2,FALSE),"x")="x"),1,0) -> 0 | J9: =TEXT(D9,"dd/mm")&" "&TEXT(E9,"HH:MM")&" - "&F9&" - "&G9&" x "&H9 -> 14/06 01:00 - grupo D - Austrália x Turquia | K9: 0 | M9: 1
A10: 9 | B10: =TEXT(D10,"ddd") -> Sun | C10: =IF(E10>0.5,D10,D10-1) -> 46187 | D10: 46187 | E10: 0.58333333 | F10: grupo E | G10: Alemanha | H10: Curaçau | I10: =IF(OR(LEFT(F10,5)<>"grupo",IFERROR(VLOOKUP(G10,chave!$B$2:$C$49,2,FALSE),"x")="x",IFERROR(VLOOKUP(H10,chave!$B$2:$C$49,2,FALSE),"x")="x"),1,0) -> 1 | J10: =TEXT(D10,"dd/mm")&" "&TEXT(E10,"HH:MM")&" - "&F10&" - "&G10&" x "&H10 -> 14/06 14:00 - grupo E - Alemanha x Curaçau | K10: 0 | M10: 1
A11: 10 | B11: =TEXT(D11,"ddd") -> Sun | C11: =IF(E11>0.5,D11,D11-1) -> 46187 | D11: 46187 | E11: 0.70833333 | F11: grupo F | G11: Holanda | H11: Japão | I11: =IF(OR(LEFT(F11,5)<>"grupo",IFERROR(VLOOKUP(G11,chave!$B$2:$C$49,2,FALSE),"x")="x",IFERROR(VLOOKUP(H11,chave!$B$2:$C$49,2,FALSE),"x")="x"),1,0) -> 1 | J11: =TEXT(D11,"dd/mm")&" "&TEXT(E11,"HH:MM")&" - "&F11&" - "&G11&" x "&H11 -> 14/06 17:00 - grupo F - Holanda x Japão | K11: 0 | L11: 0 | M11: 1
A12: 11 | B12: =TEXT(D12,"ddd") -> Sun | C12: =IF(E12>0.5,D12,D12-1) -> 46187 | D12: 46187 | E12: 0.83333333 | F12: grupo E | G12: Costa do Marfim | H12: Equador | I12: =IF(OR(LEFT(F12,5)<>"grupo",IFERROR(VLOOKUP(G12,chave!$B$2:$C$49,2,FALSE),"x")="x",IFERROR(VLOOKUP(H12,chave!$B$2:$C$49,2,FALSE),"x")="x"),1,0) -> 0 | J12: =TEXT(D12,"dd/mm")&" "&TEXT(E12,"HH:MM")&" - "&F12&" - "&G12&" x "&H12 -> 14/06 20:00 - grupo E - Costa do Marfim x Equador | M12: 1
A13: 12 | B13: =TEXT(D13,"ddd") -> Sun | C13: =IF(E13>0.5,D13,D13-1) -> 46187 | D13: 46187 | E13: 0.95833333 | F13: grupo F | G13: Suécia | H13: Tunísia | I13: =IF(OR(LEFT(F13,5)<>"grupo",IFERROR(VLOOKUP(G13,chave!$B$2:$C$49,2,FALSE),"x")="x",IFERROR(VLOOKUP(H13,chave!$B$2:$C$49,2,FALSE),"x")="x"),1,0) -> 0 | J13: =TEXT(D13,"dd/mm")&" "&TEXT(E13,"HH:MM")&" - "&F13&" - "&G13&" x "&H13 -> 14/06 23:00 - grupo F - Suécia x Tunísia | M13: 1
A14: 13 | B14: =TEXT(D14,"ddd") -> Mon | C14: =IF(E14>0.5,D14,D14-1) -> 46188 | D14: 46188 | E14: 0.54166667 | F14: grupo H | G14: Espanha | H14: Cabo Verde | I14: =IF(OR(LEFT(F14,5)<>"grupo",IFERROR(VLOOKUP(G14,chave!$B$2:$C$49,2,FALSE),"x")="x",IFERROR(VLOOKUP(H14,chave!$B$2:$C$49,2,FALSE),"x")="x"),1,0) -> 1 | J14: =TEXT(D14,"dd/mm")&" "&TEXT(E14,"HH:MM")&" - "&F14&" - "&G14&" x "&H14 -> 15/06 13:00 - grupo H - Espanha x Cabo Verde | M14: 1
A15: 14 | B15: =TEXT(D15,"ddd") -> Mon | C15: =IF(E15>0.5,D15,D15-1) -> 46188 | D15: 46188 | E15: 0.66666667 | F15: grupo G | G15: Bélgica | H15: Egito | I15: =IF(OR(LEFT(F15,5)<>"grupo",IFERROR(VLOOKUP(G15,chave!$B$2:$C$49,2,FALSE),"x")="x",IFERROR(VLOOKUP(H15,chave!$B$2:$C$49,2,FALSE),"x")="x"),1,0) -> 1 | J15: =TEXT(D15,"dd/mm")&" "&TEXT(E15,"HH:MM")&" - "&F15&" - "&G15&" x "&H15 -> 15/06 16:00 - grupo G - Bélgica x Egito | M15: 1
A16: 15 | B16: =TEXT(D16,"ddd") -> Mon | C16: =IF(E16>0.5,D16,D16-1) -> 46188 | D16: 46188 | E16: 0.79166667 | F16: grupo H | G16: Arábia Saudita | H16: Uruguai | I16: =IF(OR(LEFT(F16,5)<>"grupo",IFERROR(VLOOKUP(G16,chave!$B$2:$C$49,2,FALSE),"x")="x",IFERROR(VLOOKUP(H16,chave!$B$2:$C$49,2,FALSE),"x")="x"),1,0) -> 0 | J16: =TEXT(D16,"dd/mm")&" "&TEXT(E16,"HH:MM")&" - "&F16&" - "&G16&" x "&H16 -> 15/06 19:00 - grupo H - Arábia Saudita x Uruguai | M16: 1
A17: 16 | B17: =TEXT(D17,"ddd") -> Mon | C17: =IF(E17>0.5,D17,D17-1) -> 46188 | D17: 46188 | E17: 0.91666667 | F17: grupo G | G17: Irã | H17: Nova Zelândia | I17: =IF(OR(LEFT(F17,5)<>"grupo",IFERROR(VLOOKUP(G17,chave!$B$2:$C$49,2,FALSE),"x")="x",IFERROR(VLOOKUP(H17,chave!$B$2:$C$49,2,FALSE),"x")="x"),1,0) -> 0 | J17: =TEXT(D17,"dd/mm")&" "&TEXT(E17,"HH:MM")&" - "&F17&" - "&G17&" x "&H17 -> 15/06 22:00 - grupo G - Irã x Nova Zelândia | M17: 1
A18: 17 | B18: =TEXT(D18,"ddd") -> Tue | C18: =IF(E18>0.5,D18,D18-1) -> 46189 | D18: 46189 | E18: 0.66666667 | F18: grupo I | G18: França | H18: Senegal | I18: =IF(OR(LEFT(F18,5)<>"grupo",IFERROR(VLOOKUP(G18,chave!$B$2:$C$49,2,FALSE),"x")="x",IFERROR(VLOOKUP(H18,chave!$B$2:$C$49,2,FALSE),"x")="x"),1,0) -> 1 | J18: =TEXT(D18,"dd/mm")&" "&TEXT(E18,"HH:MM")&" - "&F18&" - "&G18&" x "&H18 -> 16/06 16:00 - grupo I - França x Senegal | M18: 1
A19: 18 | B19: =TEXT(D19,"ddd") -> Tue | C19: =IF(E19>0.5,D19,D19-1) -> 46189 | D19: 46189 | E19: 0.79166667 | F19: grupo I | G19: Iraque | H19: Noruega | I19: =IF(OR(LEFT(F19,5)<>"grupo",IFERROR(VLOOKUP(G19,chave!$B$2:$C$49,2,FALSE),"x")="x",IFERROR(VLOOKUP(H19,chave!$B$2:$C$49,2,FALSE),"x")="x"),1,0) -> 0 | J19: =TEXT(D19,"dd/mm")&" "&TEXT(E19,"HH:MM")&" - "&F19&" - "&G19&" x "&H19 -> 16/06 19:00 - grupo I - Iraque x Noruega | M19: 1
A20: 19 | B20: =TEXT(D20,"ddd") -> Tue | C20: =IF(E20>0.5,D20,D20-1) -> 46189 | D20: 46189 | E20: 0.91666667 | F20: grupo J | G20: Argentina | H20: Argélia | I20: =IF(OR(LEFT(F20,5)<>"grupo",IFERROR(VLOOKUP(G20,chave!$B$2:$C$49,2,FALSE),"x")="x",IFERROR(VLOOKUP(H20,chave!$B$2:$C$49,2,FALSE),"x")="x"),1,0) -> 1 | J20: =TEXT(D20,"dd/mm")&" "&TEXT(E20,"HH:MM")&" - "&F20&" - "&G20&" x "&H20 -> 16/06 22:00 - grupo J - Argentina x Argélia | M20: 1
A21: 20 | B21: =TEXT(D21,"ddd") -> Wed | C21: =IF(E21>0.5,D21,D21-1) -> 46189 | D21: 46190 | E21: 0.041666667 | F21: grupo J | G21: Áustria | H21: Jordânia | I21: =IF(OR(LEFT(F21,5)<>"grupo",IFERROR(VLOOKUP(G21,chave!$B$2:$C$49,2,FALSE),"x")="x",IFERROR(VLOOKUP(H21,chave!$B$2:$C$49,2,FALSE),"x")="x"),1,0) -> 0 | J21: =TEXT(D21,"dd/mm")&" "&TEXT(E21,"HH:MM")&" - "&F21&" - "&G21&" x "&H21 -> 17/06 01:00 - grupo J - Áustria x Jordânia | M21: 1
A22: 21 | B22: =TEXT(D22,"ddd") -> Wed | C22: =IF(E22>0.5,D22,D22-1) -> 46190 | D22: 46190 | E22: 0.58333333 | F22: grupo K | G22: Portugal | H22: Congo | I22: =IF(OR(LEFT(F22,5)<>"grupo",IFERROR(VLOOKUP(G22,chave!$B$2:$C$49,2,FALSE),"x")="x",IFERROR(VLOOKUP(H22,chave!$B$2:$C$49,2,FALSE),"x")="x"),1,0) -> 1 | J22: =TEXT(D22,"dd/mm")&" "&TEXT(E22,"HH:MM")&" - "&F22&" - "&G22&" x "&H22 -> 17/06 14:00 - grupo K - Portugal x Congo | M22: 1
A23: 22 | B23: =TEXT(D23,"ddd") -> Wed | C23: =IF(E23>0.5,D23,D23-1) -> 46190 | D23: 46190 | E23: 0.70833333 | F23: grupo L | G23: Inglaterra | H23: Croácia | I23: =IF(OR(LEFT(F23,5)<>"grupo",IFERROR(VLOOKUP(G23,chave!$B$2:$C$49,2,FALSE),"x")="x",IFERROR(VLOOKUP(H23,chave!$B$2:$C$49,2,FALSE),"x")="x"),1,0) -> 1 | J23: =TEXT(D23,"dd/mm")&" "&TEXT(E23,"HH:MM")&" - "&F23&" - "&G23&" x "&H23 -> 17/06 17:00 - grupo L - Inglaterra x Croácia | M23: 1
... A105: 104 | B105: =TEXT(D105,"ddd") -> Sun | C105: =IF(E105>0.5,D105,D105-1) -> 46222 | D105: 46222 | E105: 0.66666667 | F105: final | G105: Vencedor 101 | H105: Vencedor 102 | I105: =IF(OR(LEFT(F105,5)<>"grupo",IFERROR(VLOOKUP(G105,chave!$B$2:$C$49,2,FALSE),"x")="x",IFERROR(VLOOKUP(H105,chave!$B$2:$C$49,2,FALSE),"x")="x"),1,0) -> 1 | J105: =TEXT(D105,"dd/mm")&" "&TEXT(E105,"HH:MM")&" - "&F105&" - "&G105&" x "&H105 -> 19/07 16:00 - final - Vencedor 101 x Vencedor 102 | M105: 1

Sheet Palpites
A1: jogo | B1: usuario | C1: timestamp | D1: gols_selecao1 | E1: gols_selecao2
A2: 1 | B2: jbbinder@gmail.com | C2: 46158.339 | D2: 2 | E2: 3
A3: 21 | B3: jbbinder@gmail.com | C3: 46158.338 | D3: 3 | E3: 6
A4: 3 | B4: juliano3142@gmail.com | C4: 46158.356 | D4: 2 | E4: 2
A5: 3 | B5: vanialuciane@gmail.com | C5: 46158.357 | D5: 0 | E5: 2
A6: 4 | B6: juliano3142@gmail.com | C6: 46158.357 | D6: 1 | E6: 2
A7: 4 | B7: vanialuciane@gmail.com | C7: 46158.357 | D7: 1 | E7: 2
A8: 3 | B8: jbbinder@gmail.com | C8: 46164.58 | D8: 0 | E8: 14
A9: 4 | B9: jbbinder@gmail.com | C9: 46164.58 | D9: 0 | E9: 1
A10: 6 | B10: jbbinder@gmail.com | C10: 46158.391 | D10: 1 | E10: 0
A11: 9 | B11: jbbinder@gmail.com | C11: 46158.391 | D11: 1 | E11: 1
A12: 17 | B12: jbbinder@gmail.com | C12: 46158.7 | D12: 0 | E12: 1
A13: 33 | B13: jbbinder@gmail.com | C13: 46158.702 | D13: 2 | E13: 1
... A18: 13 | B18: jbbinder@gmail.com | C18: 46164.606 | D18: 0 | E18: 0

Sheet chave
A1: grupo | B1: Seleção | C1: cabeça
A2: grupo A | B2: África do Sul
A3: grupo A | B3: Coreia do Sul
A4: grupo A | B4: México | C4: x
A5: grupo A | B5: Rep. Tcheca
A6: grupo B | B6: Bósnia e H
A7: grupo B | B7: Canadá | C7: x
A8: grupo B | B8: Catar
A9: grupo B | B9: Suíça
A10: grupo C | B10: Brasil | C10: x
A11: grupo C | B11: Escócia
A12: grupo C | B12: Haiti
A13: grupo C | B13: Marrocos
A14: grupo D | B14: Austrália
A15: grupo D | B15: Estados Unidos | C15: x
A16: grupo D | B16: Paraguai
A17: grupo D | B17: Turquia
A18: grupo E | B18: Alemanha | C18: x
A19: grupo E | B19: Costa do Marfim
A20: grupo E | B20: Curaçau
A21: grupo E | B21: Equador
A22: grupo F | B22: Holanda | C22: x
A23: grupo F | B23: Japão
A24: grupo F | B24: Suécia
A25: grupo F | B25: Tunísia
A26: grupo G | B26: Bélgica | C26: x
A27: grupo G | B27: Egito
A28: grupo G | B28: Irã
A29: grupo G | B29: Nova Zelândia
A30: grupo H | B30: Arábia Saudita
A31: grupo H | B31: Cabo Verde
A32: grupo H | B32: Espanha | C32: x
A33: grupo H | B33: Uruguai
A34: grupo I | B34: França | C34: x
A35: grupo I | B35: Iraque
A36: grupo I | B36: Noruega
A37: grupo I | B37: Senegal
A38: grupo J | B38: Argélia
A39: grupo J | B39: Argentina | C39: x
A40: grupo J | B40: Áustria
...

Sheet multipl
A1: Grupo | B1: Fase | C1: multiplicador
A2: grupo A | B2: =if(left(A2,5)="grupo","grupos",A2) -> grupos | C2: 1
A3: grupo B | B3: =if(left(A3,5)="grupo","grupos",A3) -> grupos | C3: 1
A4: grupo D | B4: =if(left(A4,5)="grupo","grupos",A4) -> grupos | C4: 1
A5: grupo C | B5: =if(left(A5,5)="grupo","grupos",A5) -> grupos | C5: 1
A6: grupo E | B6: =if(left(A6,5)="grupo","grupos",A6) -> grupos | C6: 1
A7: grupo F | B7: =if(left(A7,5)="grupo","grupos",A7) -> grupos | C7: 1
A8: grupo H | B8: =if(left(A8,5)="grupo","grupos",A8) -> grupos | C8: 1
A9: grupo G | B9: =if(left(A9,5)="grupo","grupos",A9) -> grupos | C9: 1
A10: grupo I | B10: =if(left(A10,5)="grupo","grupos",A10) -> grupos | C10: 1
A11: grupo J | B11: =if(left(A11,5)="grupo","grupos",A11) -> grupos | C11: 1
A12: grupo K | B12: =if(left(A12,5)="grupo","grupos",A12) -> grupos | C12: 1
A13: grupo L | B13: =if(left(A13,5)="grupo","grupos",A13) -> grupos | C13: 1
... A19: final | B19: =if(left(A19,5)="grupo","grupos",A19) -> final | C19: 5

Sheet result
A1: =Palpites!A1 -> jogo | B1: =Palpites!B1 -> usuario | C1: =Palpites!C1 -> timestamp | D1: =Palpites!D1 -> gols_selecao1 | E1: =Palpites!E1 -> gols_selecao2 | F1: golsSel1 | G1: golsSel2 | H1: fase | I1: multiplicador | J1: pt_venc | K1: pt_placar | L1: pt_gols | M1: pt_total
A2: =Palpites!A2 -> 1 | B2: =Palpites!B2 -> jbbinder@gmail.com | C2: =Palpites!C2 -> 46158.339 | D2: =Palpites!D2 -> 2 | E2: =Palpites!E2 -> 3 | F2: =VLOOKUP(A2,tabela!$A$2:$L$105,11,false) -> 9 | G2: =VLOOKUP(A2,tabela!$A$2:$L$105,12,false) -> 9 | H2: =vlookup(vlookup(A2,tabela!$A$2:$F$105,6,false),multipl!$A$2:$C$19,2,false) -> grupos | I2: =vlookup(vlookup(A2,tabela!$A$2:$F$105,6,false),multipl!$A$2:$C$19,3,false) -> 1 | J2: =if(and(isnumber(F2),isnumber(G2)), if(sign(D2-E2)=sign(F2-G2),I2,0),0) -> 0 | K2: =if(and(isnumber(F2),isnumber(G2)),if(and(D2=F2,E2=G2),I2,0)*0.5,0) -> 0 | L2: =if(and(isnumber(F2),isnumber(G2)),if(D2+E2=F2+G2,I2,0)*0.5,0) -> 0 | M2: =sum(J2:L2) -> 0
A3: =Palpites!A3 -> 21 | B3: =Palpites!B3 -> jbbinder@gmail.com | C3: =Palpites!C3 -> 46158.338 | D3: =Palpites!D3 -> 3 | E3: =Palpites!E3 -> 6 | F3: =VLOOKUP(A3,tabela!$A$2:$L$105,11,false) | G3: =VLOOKUP(A3,tabela!$A$2:$L$105,12,false) | H3: =vlookup(vlookup(A3,tabela!$A$2:$F$105,6,false),multipl!$A$2:$C$19,2,false) -> grupos | I3: =vlookup(vlookup(A3,tabela!$A$2:$F$105,6,false),multipl!$A$2:$C$19,3,false) -> 1 | J3: =if(and(isnumber(F3),isnumber(G3)), if(sign(D3-E3)=sign(F3-G3),I3,0),0) -> 0 | K3: =if(and(isnumber(F3),isnumber(G3)),if(and(D3=F3,E3=G3),I3,0)*0.5,0) -> 0 | L3: =if(and(isnumber(F3),isnumber(G3)),if(D3+E3=F3+G3,I3,0)*0.5,0) -> 0 | M3: =sum(J3:L3) -> 0
A4: =Palpites!A4 -> 3 | B4: =Palpites!B4 -> juliano3142@gmail.com | C4: =Palpites!C4 -> 46158.356 | D4: =Palpites!D4 -> 2 | E4: =Palpites!E4 -> 2 | F4: =VLOOKUP(A4,tabela!$A$2:$L$105,11,false) -> 1 | G4: =VLOOKUP(A4,tabela!$A$2:$L$105,12,false) -> 2 | H4: =vlookup(vlookup(A4,tabela!$A$2:$F$105,6,false),multipl!$A$2:$C$19,2,false) -> grupos | I4: =vlookup(vlookup(A4,tabela!$A$2:$F$105,6,false),multipl!$A$2:$C$19,3,false) -> 1 | J4: =if(and(isnumber(F4),isnumber(G4)), if(sign(D4-E4)=sign(F4-G4),I4,0),0) -> 0 | K4: =if(and(isnumber(F4),isnumber(G4)),if(and(D4=F4,E4=G4),I4,0)*0.5,0) -> 0 | L4: =if(and(isnumber(F4),isnumber(G4)),if(D4+E4=F4+G4,I4,0)*0.5,0) -> 0 | M4: =sum(J4:L4) -> 0
A5: =Palpites!A5 -> 3 | B5: =Palpites!B5 -> vanialuciane@gmail.com | C5: =Palpites!C5 -> 46158.357 | D5: =Palpites!D5 -> 0 | E5: =Palpites!E5 -> 2 | F5: =VLOOKUP(A5,tabela!$A$2:$L$105,11,false) -> 1 | G5: =VLOOKUP(A5,tabela!$A$2:$L$105,12,false) -> 2 | H5: =vlookup(vlookup(A5,tabela!$A$2:$F$105,6,false),multipl!$A$2:$C$19,2,false) -> grupos | I5: =vlookup(vlookup(A5,tabela!$A$2:$F$105,6,false),multipl!$A$2:$C$19,3,false) -> 1 | J5: =if(and(isnumber(F5),isnumber(G5)), if(sign(D5-E5)=sign(F5-G5),I5,0),0) -> 1 | K5: =if(and(isnumber(F5),isnumber(G5)),if(and(D5=F5,E5=G5),I5,0)*0.5,0) -> 0 | L5: =if(and(isnumber(F5),isnumber(G5)),if(D5+E5=F5+G5,I5,0)*0.5,0) -> 0 | M5: =sum(J5:L5) -> 1
A6: =Palpites!A6 -> 4 | B6: =Palpites!B6 -> juliano3142@gmail.com | C6: =Palpites!C6 -> 46158.357 | D6: =Palpites!D6 -> 1 | E6: =Palpites!E6 -> 2 | F6: =VLOOKUP(A6,tabela!$A$2:$L$105,11,false) -> 0 | G6: =VLOOKUP(A6,tabela!$A$2:$L$105,12,false) | H6: =vlookup(vlookup(A6,tabela!$A$2:$F$105,6,false),multipl!$A$2:$C$19,2,false) -> grupos | I6: =vlookup(vlookup(A6,tabela!$A$2:$F$105,6,false),multipl!$A$2:$C$19,3,false) -> 1 | J6: =if(and(isnumber(F6),isnumber(G6)), if(sign(D6-E6)=sign(F6-G6),I6,0),0) -> 0 | K6: =if(and(isnumber(F6),isnumber(G6)),if(and(D6=F6,E6=G6),I6,0)*0.5,0) -> 0 | L6: =if(and(isnumber(F6),isnumber(G6)),if(D6+E6=F6+G6,I6,0)*0.5,0) -> 0 | M6: =sum(J6:L6) -> 0
A7: =Palpites!A7 -> 4 | B7: =Palpites!B7 -> vanialuciane@gmail.com | C7: =Palpites!C7 -> 46158.357 | D7: =Palpites!D7 -> 1 | E7: =Palpites!E7 -> 2 | F7: =VLOOKUP(A7,tabela!$A$2:$L$105,11,false) -> 0 | G7: =VLOOKUP(A7,tabela!$A$2:$L$105,12,false) | H7: =vlookup(vlookup(A7,tabela!$A$2:$F$105,6,false),multipl!$A$2:$C$19,2,false) -> grupos | I7: =vlookup(vlookup(A7,tabela!$A$2:$F$105,6,false),multipl!$A$2:$C$19,3,false) -> 1 | J7: =if(and(isnumber(F7),isnumber(G7)), if(sign(D7-E7)=sign(F7-G7),I7,0),0) -> 0 | K7: =if(and(isnumber(F7),isnumber(G7)),if(and(D7=F7,E7=G7),I7,0)*0.5,0) -> 0 | L7: =if(and(isnumber(F7),isnumber(G7)),if(D7+E7=F7+G7,I7,0)*0.5,0) -> 0 | M7: =sum(J7:L7) -> 0
A8: =Palpites!A8 -> 3 | B8: =Palpites!B8 -> jbbinder@gmail.com | C8: =Palpites!C8 -> 46164.58 | D8: =Palpites!D8 -> 0 | E8: =Palpites!E8 -> 14 | F8: =VLOOKUP(A8,tabela!$A$2:$L$105,11,false) -> 1 | G8: =VLOOKUP(A8,tabela!$A$2:$L$105,12,false) -> 2 | H8: =vlookup(vlookup(A8,tabela!$A$2:$F$105,6,false),multipl!$A$2:$C$19,2,false) -> grupos | I8: =vlookup(vlookup(A8,tabela!$A$2:$F$105,6,false),multipl!$A$2:$C$19,3,false) -> 1 | J8: =if(and(isnumber(F8),isnumber(G8)), if(sign(D8-E8)=sign(F8-G8),I8,0),0) -> 1 | K8: =if(and(isnumber(F8),isnumber(G8)),if(and(D8=F8,E8=G8),I8,0)*0.5,0) -> 0 | L8: =if(and(isnumber(F8),isnumber(G8)),if(D8+E8=F8+G8,I8,0)*0.5,0) -> 0 | M8: =sum(J8:L8) -> 1
A9: =Palpites!A9 -> 4 | B9: =Palpites!B9 -> jbbinder@gmail.com | C9: =Palpites!C9 -> 46164.58 | D9: =Palpites!D9 -> 0 | E9: =Palpites!E9 -> 1 | F9: =VLOOKUP(A9,tabela!$A$2:$L$105,11,false) -> 0 | G9: =VLOOKUP(A9,tabela!$A$2:$L$105,12,false) | H9: =vlookup(vlookup(A9,tabela!$A$2:$F$105,6,false),multipl!$A$2:$C$19,2,false) -> grupos | I9: =vlookup(vlookup(A9,tabela!$A$2:$F$105,6,false),multipl!$A$2:$C$19,3,false) -> 1 | J9: =if(and(isnumber(F9),isnumber(G9)), if(sign(D9-E9)=sign(F9-G9),I9,0),0) -> 0 | K9: =if(and(isnumber(F9),isnumber(G9)),if(and(D9=F9,E9=G9),I9,0)*0.5,0) -> 0 | L9: =if(and(isnumber(F9),isnumber(G9)),if(D9+E9=F9+G9,I9,0)*0.5,0) -> 0 | M9: =sum(J9:L9) -> 0
A10: =Palpites!A10 -> 6 | B10: =Palpites!B10 -> jbbinder@gmail.com | C10: =Palpites!C10 -> 46158.391 | D10: =Palpites!D10 -> 1 | E10: =Palpites!E10 -> 0 | F10: =VLOOKUP(A10,tabela!$A$2:$L$105,11,false) -> 0 | G10: =VLOOKUP(A10,tabela!$A$2:$L$105,12,false) | H10: =vlookup(vlookup(A10,tabela!$A$2:$F$105,6,false),multipl!$A$2:$C$19,2,false) -> grupos | I10: =vlookup(vlookup(A10,tabela!$A$2:$F$105,6,false),multipl!$A$2:$C$19,3,false) -> 1 | J10: =if(and(isnumber(F10),isnumber(G10)), if(sign(D10-E10)=sign(F10-G10),I10,0),0) -> 0 | K10: =if(and(isnumber(F10),isnumber(G10)),if(and(D10=F10,E10=G10),I10,0)*0.5,0) -> 0 | L10: =if(and(isnumber(F10),isnumber(G10)),if(D10+E10=F10+G10,I10,0)*0.5,0) -> 0 | M10: =sum(J10:L10) -> 0
A11: =Palpites!A11 -> 9 | B11: =Palpites!B11 -> jbbinder@gmail.com | C11: =Palpites!C11 -> 46158.391 | D11: =Palpites!D11 -> 1 | E11: =Palpites!E11 -> 1 | F11: =VLOOKUP(A11,tabela!$A$2:$L$105,11,false) -> 0 | G11: =VLOOKUP(A11,tabela!$A$2:$L$105,12,false) | H11: =vlookup(vlookup(A11,tabela!$A$2:$F$105,6,false),multipl!$A$2:$C$19,2,false) -> grupos | I11: =vlookup(vlookup(A11,tabela!$A$2:$F$105,6,false),multipl!$A$2:$C$19,3,false) -> 1 | J11: =if(and(isnumber(F11),isnumber(G11)), if(sign(D11-E11)=sign(F11-G11),I11,0),0) -> 0 | K11: =if(and(isnumber(F11),isnumber(G11)),if(and(D11=F11,E11=G11),I11,0)*0.5,0) -> 0 | L11: =if(and(isnumber(F11),isnumber(G11)),if(D11+E11=F11+G11,I11,0)*0.5,0) -> 0 | M11: =sum(J11:L11) -> 0
A12: =Palpites!A12 -> 17 | B12: =Palpites!B12 -> jbbinder@gmail.com | C12: =Palpites!C12 -> 46158.7 | D12: =Palpites!D12 -> 0 | E12: =Palpites!E12 -> 1 | F12: =VLOOKUP(A12,tabela!$A$2:$L$105,11,false) | G12: =VLOOKUP(A12,tabela!$A$2:$L$105,12,false) | H12: =vlookup(vlookup(A12,tabela!$A$2:$F$105,6,false),multipl!$A$2:$C$19,2,false) -> grupos | I12: =vlookup(vlookup(A12,tabela!$A$2:$F$105,6,false),multipl!$A$2:$C$19,3,false) -> 1 | J12: =if(and(isnumber(F12),isnumber(G12)), if(sign(D12-E12)=sign(F12-G12),I12,0),0) -> 0 | K12: =if(and(isnumber(F12),isnumber(G12)),if(and(D12=F12,E12=G12),I12,0)*0.5,0) -> 0 | L12: =if(and(isnumber(F12),isnumber(G12)),if(D12+E12=F12+G12,I12,0)*0.5,0) -> 0 | M12: =sum(J12:L12) -> 0
A13: =Palpites!A13 -> 33 | B13: =Palpites!B13 -> jbbinder@gmail.com | C13: =Palpites!C13 -> 46158.702 | D13: =Palpites!D13 -> 2 | E13: =Palpites!E13 -> 1 | F13: =VLOOKUP(A13,tabela!$A$2:$L$105,11,false) | G13: =VLOOKUP(A13,tabela!$A$2:$L$105,12,false) | H13: =vlookup(vlookup(A13,tabela!$A$2:$F$105,6,false),multipl!$A$2:$C$19,2,false) -> grupos | I13: =vlookup(vlookup(A13,tabela!$A$2:$F$105,6,false),multipl!$A$2:$C$19,3,false) -> 1 | J13: =if(and(isnumber(F13),isnumber(G13)), if(sign(D13-E13)=sign(F13-G13),I13,0),0) -> 0 | K13: =if(and(isnumber(F13),isnumber(G13)),if(and(D13=F13,E13=G13),I13,0)*0.5,0) -> 0 | L13: =if(and(isnumber(F13),isnumber(G13)),if(D13+E13=F13+G13,I13,0)*0.5,0) -> 0 | M13: =sum(J13:L13) -> 0
... A18: =Palpites!A18 -> 13 | B18: =Palpites!B18 -> jbbinder@gmail.com | C18: =Palpites!C18 -> 46164.606 | D18: =Palpites!D18 -> 0 | E18: =Palpites!E18 -> 0 | F18: =VLOOKUP(A18,tabela!$A$2:$L$105,11,false) | G18: =VLOOKUP(A18,tabela!$A$2:$L$105,12,false) | H18: =vlookup(vlookup(A18,tabela!$A$2:$F$105,6,false),multipl!$A$2:$C$19,2,false) -> grupos | I18: =vlookup(vlookup(A18,tabela!$A$2:$F$105,6,false),multipl!$A$2:$C$19,3,false) -> 1 | J18: =if(and(isnumber(F18),isnumber(G18)), if(sign(D18-E18)=sign(F18-G18),I18,0),0) -> 0 | K18: =if(and(isnumber(F18),isnumber(G18)),if(and(D18=F18,E18=G18),I18,0)*0.5,0) -> 0 | L18: =if(and(isnumber(F18),isnumber(G18)),if(D18+E18=F18+G18,I18,0)*0.5,0) -> 0 | M18: =sum(J18:L18) -> 0
A19: =Palpites!A19 | B19: =Palpites!B19 | C19: =Palpites!C19 | D19: =Palpites!D19 | E19: =Palpites!E19
A20: =Palpites!A20 | B20: =Palpites!B20 | C20: =Palpites!C20 | D20: =Palpites!D20 | E20: =Palpites!E20
A21: =Palpites!A21 | B21: =Palpites!B21 | C21: =Palpites!C21 | D21: =Palpites!D21 | E21: =Palpites!E21
A22: =Palpites!A22 | B22: =Palpites!B22 | C22: =Palpites!C22 | D22: =Palpites!D22 | E22: =Palpites!E22
A23: =Palpites!A23 | B23: =Palpites!B23 | C23: =Palpites!C23 | D23: =Palpites!D23 | E23: =Palpites!E23
A24: =Palpites!A24 | B24: =Palpites!B24 | C24: =Palpites!C24 | D24: =Palpites!D24 | E24: =Palpites!E24
A25: =Palpites!A25 | B25: =Palpites!B25 | C25: =Palpites!C25 | D25: =Palpites!D25 | E25: =Palpites!E25
A26: =Palpites!A26 | B26: =Palpites!B26 | C26: =Palpites!C26 | D26: =Palpites!D26 | E26: =Palpites!E26
A27: =Palpites!A27 | B27: =Palpites!B27 | C27: =Palpites!C27 | D27: =Palpites!D27 | E27: =Palpites!E27
A28: =Palpites!A28 | B28: =Palpites!B28 | C28: =Palpites!C28 | D28: =Palpites!D28 | E28: =Palpites!E28

Sheet placar_tipo
A1: usuario | B1: pt_venc | C1: pt_placar | D1: pt_gols | E1: pt_total
A2: {=unique(result!B2:B18)} -> jbbinder@gmail.com | B2: =sumifs(result!J:J,result!$B:$B,$A2) -> 2 | C2: =sumifs(result!K:K,result!$B:$B,$A2) -> 0 | D2: =sumifs(result!L:L,result!$B:$B,$A2) -> 0 | E2: =sumifs(result!M:M,result!$B:$B,$A2) -> 2
A3: juliano3142@gmail.com | B3: =sumifs(result!J:J,result!$B:$B,$A3) -> 0 | C3: =sumifs(result!K:K,result!$B:$B,$A3) -> 0 | D3: =sumifs(result!L:L,result!$B:$B,$A3) -> 0 | E3: =sumifs(result!M:M,result!$B:$B,$A3) -> 0
A4: vanialuciane@gmail.com | B4: =sumifs(result!J:J,result!$B:$B,$A4) -> 1 | C4: =sumifs(result!K:K,result!$B:$B,$A4) -> 0 | D4: =sumifs(result!L:L,result!$B:$B,$A4) -> 0 | E4: =sumifs(result!M:M,result!$B:$B,$A4) -> 1
B5: =sumifs(result!J:J,result!$B:$B,$A5) -> 0 | C5: =sumifs(result!K:K,result!$B:$B,$A5) -> 0 | D5: =sumifs(result!L:L,result!$B:$B,$A5) -> 0 | E5: =sumifs(result!M:M,result!$B:$B,$A5) -> 0
B6: =sumifs(result!J:J,result!$B:$B,$A6) -> 0 | C6: =sumifs(result!K:K,result!$B:$B,$A6) -> 0 | D6: =sumifs(result!L:L,result!$B:$B,$A6) -> 0 | E6: =sumifs(result!M:M,result!$B:$B,$A6) -> 0
B7: =sumifs(result!J:J,result!$B:$B,$A7) -> 0 | C7: =sumifs(result!K:K,result!$B:$B,$A7) -> 0 | D7: =sumifs(result!L:L,result!$B:$B,$A7) -> 0 | E7: =sumifs(result!M:M,result!$B:$B,$A7) -> 0
B8: =sumifs(result!J:J,result!$B:$B,$A8) -> 0 | C8: =sumifs(result!K:K,result!$B:$B,$A8) -> 0 | D8: =sumifs(result!L:L,result!$B:$B,$A8) -> 0 | E8: =sumifs(result!M:M,result!$B:$B,$A8) -> 0
B9: =sumifs(result!J:J,result!$B:$B,$A9) -> 0 | C9: =sumifs(result!K:K,result!$B:$B,$A9) -> 0 | D9: =sumifs(result!L:L,result!$B:$B,$A9) -> 0 | E9: =sumifs(result!M:M,result!$B:$B,$A9) -> 0
B10: =sumifs(result!J:J,result!$B:$B,$A10) -> 0 | C10: =sumifs(result!K:K,result!$B:$B,$A10) -> 0 | D10: =sumifs(result!L:L,result!$B:$B,$A10) -> 0 | E10: =sumifs(result!M:M,result!$B:$B,$A10) -> 0
B11: =sumifs(result!J:J,result!$B:$B,$A11) -> 0 | C11: =sumifs(result!K:K,result!$B:$B,$A11) -> 0 | D11: =sumifs(result!L:L,result!$B:$B,$A11) -> 0 | E11: =sumifs(result!M:M,result!$B:$B,$A11) -> 0
B12: =sumifs(result!J:J,result!$B:$B,$A12) -> 0 | C12: =sumifs(result!K:K,result!$B:$B,$A12) -> 0 | D12: =sumifs(result!L:L,result!$B:$B,$A12) -> 0 | E12: =sumifs(result!M:M,result!$B:$B,$A12) -> 0
B13: =sumifs(result!J:J,result!$B:$B,$A13) -> 0 | C13: =sumifs(result!K:K,result!$B:$B,$A13) -> 0 | D13: =sumifs(result!L:L,result!$B:$B,$A13) -> 0 | E13: =sumifs(result!M:M,result!$B:$B,$A13) -> 0
B14: =sumifs(result!J:J,result!$B:$B,$A14) -> 0 | C14: =sumifs(result!K:K,result!$B:$B,$A14) -> 0 | D14: =sumifs(result!L:L,result!$B:$B,$A14) -> 0 | E14: =sumifs(result!M:M,result!$B:$B,$A14) -> 0
B15: =sumifs(result!J:J,result!$B:$B,$A15) -> 0 | C15: =sumifs(result!K:K,result!$B:$B,$A15) -> 0 | D15: =sumifs(result!L:L,result!$B:$B,$A15) -> 0 | E15: =sumifs(result!M:M,result!$B:$B,$A15) -> 0
B16: =sumifs(result!J:J,result!$B:$B,$A16) -> 0 | C16: =sumifs(result!K:K,result!$B:$B,$A16) -> 0 | D16: =sumifs(result!L:L,result!$B:$B,$A16) -> 0 | E16: =sumifs(result!M:M,result!$B:$B,$A16) -> 0
... B21: =sumifs(result!J:J,result!$B:$B,$A21) -> 0 | C21: =sumifs(result!K:K,result!$B:$B,$A21) -> 0 | D21: =sumifs(result!L:L,result!$B:$B,$A21) -> 0 | E21: =sumifs(result!M:M,result!$B:$B,$A21) -> 0

Sheet placar_fase
A1: usuario | B1: grupos | C1: 16-avos | D1: oitavas | E1: quartas | F1: semifinal | G1: 3.o lugar | H1: final | I1: total
A2: {=unique(result!B2:B18)} -> jbbinder@gmail.com | B2: =sumifs(result!$M:$M,result!$B:$B,$A2,result!$H:$H,B$1) -> 2 | C2: =sumifs(result!$M:$M,result!$B:$B,$A2,result!$H:$H,C$1) -> 0 | D2: =sumifs(result!$M:$M,result!$B:$B,$A2,result!$H:$H,D$1) -> 0 | E2: =sumifs(result!$M:$M,result!$B:$B,$A2,result!$H:$H,E$1) -> 0 | F2: =sumifs(result!$M:$M,result!$B:$B,$A2,result!$H:$H,F$1) -> 0 | G2: =sumifs(result!$M:$M,result!$B:$B,$A2,result!$H:$H,G$1) -> 0 | H2: =sumifs(result!$M:$M,result!$B:$B,$A2,result!$H:$H,H$1) -> 0 | I2: =sum(B2:H2) -> 2
A3: juliano3142@gmail.com | B3: =sumifs(result!$M:$M,result!$B:$B,$A3,result!$H:$H,B$1) -> 0 | C3: =sumifs(result!$M:$M,result!$B:$B,$A3,result!$H:$H,C$1) -> 0 | D3: =sumifs(result!$M:$M,result!$B:$B,$A3,result!$H:$H,D$1) -> 0 | E3: =sumifs(result!$M:$M,result!$B:$B,$A3,result!$H:$H,E$1) -> 0 | F3: =sumifs(result!$M:$M,result!$B:$B,$A3,result!$H:$H,F$1) -> 0 | G3: =sumifs(result!$M:$M,result!$B:$B,$A3,result!$H:$H,G$1) -> 0 | H3: =sumifs(result!$M:$M,result!$B:$B,$A3,result!$H:$H,H$1) -> 0 | I3: =sum(B3:H3) -> 0
A4: vanialuciane@gmail.com | B4: =sumifs(result!$M:$M,result!$B:$B,$A4,result!$H:$H,B$1) -> 1 | C4: =sumifs(result!$M:$M,result!$B:$B,$A4,result!$H:$H,C$1) -> 0 | D4: =sumifs(result!$M:$M,result!$B:$B,$A4,result!$H:$H,D$1) -> 0 | E4: =sumifs(result!$M:$M,result!$B:$B,$A4,result!$H:$H,E$1) -> 0 | F4: =sumifs(result!$M:$M,result!$B:$B,$A4,result!$H:$H,F$1) -> 0 | G4: =sumifs(result!$M:$M,result!$B:$B,$A4,result!$H:$H,G$1) -> 0 | H4: =sumifs(result!$M:$M,result!$B:$B,$A4,result!$H:$H,H$1) -> 0 | I4: =sum(B4:H4) -> 1
B5: =sumifs(result!$M:$M,result!$B:$B,$A5,result!$H:$H,B$1) -> 0 | C5: =sumifs(result!$M:$M,result!$B:$B,$A5,result!$H:$H,C$1) -> 0 | D5: =sumifs(result!$M:$M,result!$B:$B,$A5,result!$H:$H,D$1) -> 0 | E5: =sumifs(result!$M:$M,result!$B:$B,$A5,result!$H:$H,E$1) -> 0 | F5: =sumifs(result!$M:$M,result!$B:$B,$A5,result!$H:$H,F$1) -> 0 | G5: =sumifs(result!$M:$M,result!$B:$B,$A5,result!$H:$H,G$1) -> 0 | H5: =sumifs(result!$M:$M,result!$B:$B,$A5,result!$H:$H,H$1) -> 0 | I5: =sum(B5:H5) -> 0
B6: =sumifs(result!$M:$M,result!$B:$B,$A6,result!$H:$H,B$1) -> 0 | C6: =sumifs(result!$M:$M,result!$B:$B,$A6,result!$H:$H,C$1) -> 0 | D6: =sumifs(result!$M:$M,result!$B:$B,$A6,result!$H:$H,D$1) -> 0 | E6: =sumifs(result!$M:$M,result!$B:$B,$A6,result!$H:$H,E$1) -> 0 | F6: =sumifs(result!$M:$M,result!$B:$B,$A6,result!$H:$H,F$1) -> 0 | G6: =sumifs(result!$M:$M,result!$B:$B,$A6,result!$H:$H,G$1) -> 0 | H6: =sumifs(result!$M:$M,result!$B:$B,$A6,result!$H:$H,H$1) -> 0 | I6: =sum(B6:H6) -> 0
B7: =sumifs(result!$M:$M,result!$B:$B,$A7,result!$H:$H,B$1) -> 0 | C7: =sumifs(result!$M:$M,result!$B:$B,$A7,result!$H:$H,C$1) -> 0 | D7: =sumifs(result!$M:$M,result!$B:$B,$A7,result!$H:$H,D$1) -> 0 | E7: =sumifs(result!$M:$M,result!$B:$B,$A7,result!$H:$H,E$1) -> 0 | F7: =sumifs(result!$M:$M,result!$B:$B,$A7,result!$H:$H,F$1) -> 0 | G7: =sumifs(result!$M:$M,result!$B:$B,$A7,result!$H:$H,G$1) -> 0 | H7: =sumifs(result!$M:$M,result!$B:$B,$A7,result!$H:$H,H$1) -> 0 | I7: =sum(B7:H7) -> 0
B8: =sumifs(result!$M:$M,result!$B:$B,$A8,result!$H:$H,B$1) -> 0 | C8: =sumifs(result!$M:$M,result!$B:$B,$A8,result!$H:$H,C$1) -> 0 | D8: =sumifs(result!$M:$M,result!$B:$B,$A8,result!$H:$H,D$1) -> 0 | E8: =sumifs(result!$M:$M,result!$B:$B,$A8,result!$H:$H,E$1) -> 0 | F8: =sumifs(result!$M:$M,result!$B:$B,$A8,result!$H:$H,F$1) -> 0 | G8: =sumifs(result!$M:$M,result!$B:$B,$A8,result!$H:$H,G$1) -> 0 | H8: =sumifs(result!$M:$M,result!$B:$B,$A8,result!$H:$H,H$1) -> 0 | I8: =sum(B8:H8) -> 0
B9: =sumifs(result!$M:$M,result!$B:$B,$A9,result!$H:$H,B$1) -> 0 | C9: =sumifs(result!$M:$M,result!$B:$B,$A9,result!$H:$H,C$1) -> 0 | D9: =sumifs(result!$M:$M,result!$B:$B,$A9,result!$H:$H,D$1) -> 0 | E9: =sumifs(result!$M:$M,result!$B:$B,$A9,result!$H:$H,E$1) -> 0 | F9: =sumifs(result!$M:$M,result!$B:$B,$A9,result!$H:$H,F$1) -> 0 | G9: =sumifs(result!$M:$M,result!$B:$B,$A9,result!$H:$H,G$1) -> 0 | H9: =sumifs(result!$M:$M,result!$B:$B,$A9,result!$H:$H,H$1) -> 0 | I9: =sum(B9:H9) -> 0
B10: =sumifs(result!$M:$M,result!$B:$B,$A10,result!$H:$H,B$1) -> 0 | C10: =sumifs(result!$M:$M,result!$B:$B,$A10,result!$H:$H,C$1) -> 0 | D10: =sumifs(result!$M:$M,result!$B:$B,$A10,result!$H:$H,D$1) -> 0 | E10: =sumifs(result!$M:$M,result!$B:$B,$A10,result!$H:$H,E$1) -> 0 | F10: =sumifs(result!$M:$M,result!$B:$B,$A10,result!$H:$H,F$1) -> 0 | G10: =sumifs(result!$M:$M,result!$B:$B,$A10,result!$H:$H,G$1) -> 0 | H10: =sumifs(result!$M:$M,result!$B:$B,$A10,result!$H:$H,H$1) -> 0 | I10: =sum(B10:H10) -> 0
B11: =sumifs(result!$M:$M,result!$B:$B,$A11,result!$H:$H,B$1) -> 0 | C11: =sumifs(result!$M:$M,result!$B:$B,$A11,result!$H:$H,C$1) -> 0 | D11: =sumifs(result!$M:$M,result!$B:$B,$A11,result!$H:$H,D$1) -> 0 | E11: =sumifs(result!$M:$M,result!$B:$B,$A11,result!$H:$H,E$1) -> 0 | F11: =sumifs(result!$M:$M,result!$B:$B,$A11,result!$H:$H,F$1) -> 0 | G11: =sumifs(result!$M:$M,result!$B:$B,$A11,result!$H:$H,G$1) -> 0 | H11: =sumifs(result!$M:$M,result!$B:$B,$A11,result!$H:$H,H$1) -> 0 | I11: =sum(B11:H11) -> 0
B12: =sumifs(result!$M:$M,result!$B:$B,$A12,result!$H:$H,B$1) -> 0 | C12: =sumifs(result!$M:$M,result!$B:$B,$A12,result!$H:$H,C$1) -> 0 | D12: =sumifs(result!$M:$M,result!$B:$B,$A12,result!$H:$H,D$1) -> 0 | E12: =sumifs(result!$M:$M,result!$B:$B,$A12,result!$H:$H,E$1) -> 0 | F12: =sumifs(result!$M:$M,result!$B:$B,$A12,result!$H:$H,F$1) -> 0 | G12: =sumifs(result!$M:$M,result!$B:$B,$A12,result!$H:$H,G$1) -> 0 | H12: =sumifs(result!$M:$M,result!$B:$B,$A12,result!$H:$H,H$1) -> 0 | I12: =sum(B12:H12) -> 0
B13: =sumifs(result!$M:$M,result!$B:$B,$A13,result!$H:$H,B$1) -> 0 | C13: =sumifs(result!$M:$M,result!$B:$B,$A13,result!$H:$H,C$1) -> 0 | D13: =sumifs(result!$M:$M,result!$B:$B,$A13,result!$H:$H,D$1) -> 0 | E13: =sumifs(result!$M:$M,result!$B:$B,$A13,result!$H:$H,E$1) -> 0 | F13: =sumifs(result!$M:$M,result!$B:$B,$A13,result!$H:$H,F$1) -> 0 | G13: =sumifs(result!$M:$M,result!$B:$B,$A13,result!$H:$H,G$1) -> 0 | H13: =sumifs(result!$M:$M,result!$B:$B,$A13,result!$H:$H,H$1) -> 0 | I13: =sum(B13:H13) -> 0
B14: =sumifs(result!$M:$M,result!$B:$B,$A14,result!$H:$H,B$1) -> 0 | C14: =sumifs(result!$M:$M,result!$B:$B,$A14,result!$H:$H,C$1) -> 0 | D14: =sumifs(result!$M:$M,result!$B:$B,$A14,result!$H:$H,D$1) -> 0 | E14: =sumifs(result!$M:$M,result!$B:$B,$A14,result!$H:$H,E$1) -> 0 | F14: =sumifs(result!$M:$M,result!$B:$B,$A14,result!$H:$H,F$1) -> 0 | G14: =sumifs(result!$M:$M,result!$B:$B,$A14,result!$H:$H,G$1) -> 0 | H14: =sumifs(result!$M:$M,result!$B:$B,$A14,result!$H:$H,H$1) -> 0 | I14: =sum(B14:H14) -> 0
B15: =sumifs(result!$M:$M,result!$B:$B,$A15,result!$H:$H,B$1) -> 0 | C15: =sumifs(result!$M:$M,result!$B:$B,$A15,result!$H:$H,C$1) -> 0 | D15: =sumifs(result!$M:$M,result!$B:$B,$A15,result!$H:$H,D$1) -> 0 | E15: =sumifs(result!$M:$M,result!$B:$B,$A15,result!$H:$H,E$1) -> 0 | F15: =sumifs(result!$M:$M,result!$B:$B,$A15,result!$H:$H,F$1) -> 0 | G15: =sumifs(result!$M:$M,result!$B:$B,$A15,result!$H:$H,G$1) -> 0 | H15: =sumifs(result!$M:$M,result!$B:$B,$A15,result!$H:$H,H$1) -> 0 | I15: =sum(B15:H15) -> 0
B16: =sumifs(result!$M:$M,result!$B:$B,$A16,result!$H:$H,B$1) -> 0 | C16: =sumifs(result!$M:$M,result!$B:$B,$A16,result!$H:$H,C$1) -> 0 | D16: =sumifs(result!$M:$M,result!$B:$B,$A16,result!$H:$H,D$1) -> 0 | E16: =sumifs(result!$M:$M,result!$B:$B,$A16,result!$H:$H,E$1) -> 0 | F16: =sumifs(result!$M:$M,result!$B:$B,$A16,result!$H:$H,F$1) -> 0 | G16: =sumifs(result!$M:$M,result!$B:$B,$A16,result!$H:$H,G$1) -> 0 | H16: =sumifs(result!$M:$M,result!$B:$B,$A16,result!$H:$H,H$1) -> 0 | I16: =sum(B16:H16) -> 0
... B21: =sumifs(result!$M:$M,result!$B:$B,$A21,result!$H:$H,B$1) -> 0 | C21: =sumifs(result!$M:$M,result!$B:$B,$A21,result!$H:$H,C$1) -> 0 | D21: =sumifs(result!$M:$M,result!$B:$B,$A21,result!$H:$H,D$1) -> 0 | E21: =sumifs(result!$M:$M,result!$B:$B,$A21,result!$H:$H,E$1) -> 0 | F21: =sumifs(result!$M:$M,result!$B:$B,$A21,result!$H:$H,F$1) -> 0 | G21: =sumifs(result!$M:$M,result!$B:$B,$A21,result!$H:$H,G$1) -> 0 | H21: =sumifs(result!$M:$M,result!$B:$B,$A21,result!$H:$H,H$1) -> 0 | I21: =sum(B21:H21) -> 0
